Workbook

Sheet PRODUTOS
A1: Despesas | C1: 0.2 | D1: Data Atualização | H1: Despesas Fixas | J1: 4100 | L1: PV | M1: =IF(N2=1,N5,IF(N2=2,M5,"ERRO")) -> 8000 | N1: 1-Digitado, 2- V Desejo
A2: LUCRO DESEJADO | C2: 0.5 | D2: 44306 | H2: Ponto de equlibrio | J2: =J1/J3 -> 5987.5012 | L2: Desp F | M2: =-J1 -> -4100 | N2: 1
A3: Taxas | B3: Aplicativos | C3: Taxa | D3: Online | E3: cartão | F3: TOTAL | H3: % IMC | J3: =I6 -> 0.68475977 | L3: Cutsos V | M3: =-(1-J3)*M1 -> -2521.9218 | N3: =IF(N2=1,"Ponto E",IF(N2=2,"V Desejo")) -> Ponto E
B4: Vendas Presencial | C4: 0 | D4: 0 | E4: 0.0494 | F4: =SUM(C4:E4) -> 0.0494 | L4: LUCRO | M4: =SUM(M1:M3) -> 1378.0782 | N4: =M4/M1 -> 0.17225977
B5: Ifood | C5: 0.12 | D5: 0.035 | E5: 0 | F5: 0.171 | L5: desejado | M5: =-M2/(1-C2-F8) -> 27107.438 | N5: 8000 | O5: Digite Vendas Totais/Mês
B6: Quero Delivery | C6: 0.08 | D6: 0.0499 | E6: 0 | F6: 0.13 | G6: =AVERAGE(G8:G166) -> 77.787933 | H6: =AVERAGE(H8:H166) -> 53.266048 | I6: =H6/G6 -> 0.68475977 | J6: =AVERAGE(J8:J166) -> 37.708461 | K6: =J6/G6 -> 0.48475977
A7: CÓDIGO | B7: Nome do Produto | C7: Custo unit | D7: Qt | E7: preço Cient | F7: % Custo | G7: PV-Prática | H7: MC | I7: %MC | J7: lucro prat | K7: % Lucro Prat | M7: MARKUP
A8: 501 | B8: P A S T E L | C8: =C10 -> 4.7896 | D8: 1 | E8: =C8/(1-$C$1-$C$2-$F$4) -> 19.11253 | F8: =IFERROR(C8/G8,"")+$F$4 -> 0.34875 | G8: 16 | H8: =IF(G8="","",G8-C8-($F$4)*G8) -> 10.42 | I8: =IF(G8="","",H8/G8) -> 0.65125 | J8: =IF(G8="","",H8-G8*($C$1)) -> 7.22 | K8: =IFERROR(J8/G8,"") -> 0.45125
A9: =A8+200 -> 701 | B9: BROWNIE NO POTE Ifood | C9: =C10 -> 4.7896 | D9: 1 | E9: =(E8/(1-$F$5)) -> 23.054922 | F9: =IFERROR(C9/G9,"")+$F$5 -> 0.3787474 | G9: =E9 -> 23.054922 | H9: =IF(G9="","",G9-C9-($F$5)*G9) -> 14.32293 | I9: =IF(G9="","",H9/G9) -> 0.6212526 | J9: =IF(G9="","",H9-G9*$C$1) -> 9.7119456 | K9: =IFERROR(J9/G9,"") -> 0.4212526 | L9: 1 | M9: 1
A10: =A8+400 -> 901 | B10: BROWNIE NO POTE Quero | C10: =Violino!C3:D3 -> 4.7896 | D10: 1 | E10: =E8/(1-$F$6) -> 21.968425 | F10: =IFERROR(C10/G10,"")+$F$6 -> 0.348022 | G10: =E10 -> 21.968425 | H10: =IF(G10="","",G10-C10-($F$6)*G10) -> 14.32293 | I10: =IF(G10="","",H10/G10) -> 0.651978 | J10: =IF(G10="","",H10-G10*$C$1) -> 9.9292449 | K10: =IFERROR(J10/G10,"") -> 0.451978 | L10: 0.87 | M10: 0.829
A11: =A8+1 -> 502 | B11: BOLO GELADO ABACAXI | C11: ='BOLO GELADO ABACAXI'!C3:D3 -> 99.690995 | D11: 1 | E11: =C11/(1-$C$1-$C$2-$F$4) -> 397.80924 | F11: =IFERROR(C11/G11,"")+$F$4 -> 6.6954663 | G11: 15 | H11: =IF(G11="","",G11-C11-($F$4)*G11) -> -85.431995 | I11: =IF(G11="","",H11/G11) -> -5.6954663 | J11: =IF(G11="","",H11-G11*$C$1) -> -88.431995 | K11: =IFERROR(J11/G11,"") -> -5.8954663 | L11: =L10-L9 -> -0.13 | M11: =M10-M9 -> -0.171
A12: =A11+200 -> 702 | B12: BOLO GELADO ABACAXI ifood | C12: =C11 -> 99.690995 | D12: 1 | E12: =C12/(1-$C$1-$C$2-$F$5) -> 772.79841 | F12: =IFERROR(C12/G12,"")+$F$5 -> 0.3 | G12: =E12 -> 772.79841 | H12: =IF(G12="","",G12-C12-($F$5)*G12) -> 540.95888 | I12: =IF(G12="","",H12/G12) -> 0.7 | J12: =IF(G12="","",H12-G12*$C$1) -> 386.3992 | K12: =IFERROR(J12/G12,"") -> 0.5
A13: =A11+400 -> 902 | B13: BOLO GELADO ABACAXI Quero | C13: =C11 -> 99.690995 | D13: 1 | E13: =C13/(1-$C$1-$C$2-$F$6) -> 586.41761 | F13: =IFERROR(C13/G13,"")+$F$6 -> 0.3 | G13: =E13 -> 586.41761 | H13: =IF(G13="","",G13-C13-($F$6)*G13) -> 410.49233 | I13: =IF(G13="","",H13/G13) -> 0.7 | J13: =IF(G13="","",H13-G13*$C$1) -> 293.20881 | K13: =IFERROR(J13/G13,"") -> 0.5
A14: =A11+1 -> 503 | B14: BRIGADEIRO DUO | C14: ='BRIG COLHER'!C3:D3 -> 4.5661438 | D14: 1 | E14: =C14/(1-$C$1-$C$2-$F$4) -> 18.220845 | F14: =IFERROR(C14/G14,"")+$F$4 -> 0.3 | G14: =E14 -> 18.220845 | H14: =IF(G14="","",G14-C14-($F$4)*G14) -> 12.754592 | I14: =IF(G14="","",H14/G14) -> 0.7 | J14: =IF(G14="","",H14-G14*$C$1) -> 9.1104226 | K14: =IFERROR(J14/G14,"") -> 0.5
A15: =A14+200 -> 703 | B15: BRIGADEIRO DUO ifood | C15: =C14 -> 4.5661438 | D15: 1 | E15: =C15/(1-$C$1-$C$2-$F$5) -> 35.396463 | F15: =IFERROR(C15/G15,"")+$F$5 -> 0.3 | G15: =E15 -> 35.396463 | H15: =IF(G15="","",G15-C15-($F$5)*G15) -> 24.777524 | I15: =IF(G15="","",H15/G15) -> 0.7 | J15: =IF(G15="","",H15-G15*$C$1) -> 17.698232 | K15: =IFERROR(J15/G15,"") -> 0.5
A16: =A14+400 -> 903 | B16: BRIGADEIRO DUO Quero | C16: =C14 -> 4.5661438 | D16: 1 | E16: =C16/(1-$C$1-$C$2-$F$6) -> 26.859669 | F16: =IFERROR(C16/G16,"")+$F$6 -> 0.3 | G16: =E16 -> 26.859669 | H16: =IF(G16="","",G16-C16-($F$6)*G16) -> 18.801769 | I16: =IF(G16="","",H16/G16) -> 0.7 | J16: =IF(G16="","",H16-G16*$C$1) -> 13.429835 | K16: =IFERROR(J16/G16,"") -> 0.5
A17: =A14+1 -> 504 | B17: BRIGADEIRO DE COLHER | C17: ='BRIG COLHER'!C4:D4 -> 9 | D17: 1 | E17: =C17/(1-$C$1-$C$2-$F$4) -> 35.913807 | F17: =IFERROR(C17/G17,"")+$F$4 -> 0.3 | G17: =E17 -> 35.913807 | H17: =IF(G17="","",G17-C17-($F$4)*G17) -> 25.139665 | I17: =IF(G17="","",H17/G17) -> 0.7 | J17: =IF(G17="","",H17-G17*$C$1) -> 17.956903 | K17: =IFERROR(J17/G17,"") -> 0.5
A18: =A17+200 -> 704 | B18: BRIGADEIRO DE COLHER ifood | C18: =C17 -> 9 | D18: 1 | E18: =C18/(1-$C$1-$C$2-$F$5) -> 69.767442 | F18: =IFERROR(C18/G18,"")+$F$5 -> 0.3 | G18: =E18 -> 69.767442 | H18: =IF(G18="","",G18-C18-($F$5)*G18) -> 48.837209 | I18: =IF(G18="","",H18/G18) -> 0.7 | J18: =IF(G18="","",H18-G18*$C$1) -> 34.883721 | K18: =IFERROR(J18/G18,"") -> 0.5
A19: =A17+400 -> 904 | B19: BRIGADEIRO DE COLHER Quero | C19: =C17 -> 9 | D19: 1 | E19: =C19/(1-$C$1-$C$2-$F$6) -> 52.941176 | F19: =IFERROR(C19/G19,"")+$F$6 -> 0.3 | G19: =E19 -> 52.941176 | H19: =IF(G19="","",G19-C19-($F$6)*G19) -> 37.058824 | I19: =IF(G19="","",H19/G19) -> 0.7 | J19: =IF(G19="","",H19-G19*$C$1) -> 26.470588 | K19: =IFERROR(J19/G19,"") -> 0.5
A20: =A17+1 -> 505 | B20: BRIGADEIRO UNITÁRIO | C20: ='BRIG UNITARIO'!C3:D3 -> 2.5251275 | D20: 1 | E20: =C20/(1-$C$1-$C$2-$F$4) -> 10.076327 | F20: =IFERROR(C20/G20,"")+$F$4 -> 0.3 | G20: =E20 -> 10.076327 | H20: =IF(G20="","",G20-C20-($F$4)*G20) -> 7.0534286 | I20: =IF(G20="","",H20/G20) -> 0.7 | J20: =IF(G20="","",H20-G20*$C$1) -> 5.0381633 | K20: =IFERROR(J20/G20,"") -> 0.5
A21: =A20+200 -> 705 | B21: BRIGADEIRO UNITÁRIO ifood | C21: =C20 -> 2.5251275 | D21: 1 | E21: =C21/(1-$C$1-$C$2-$F$5) -> 19.574631 | F21: =IFERROR(C21/G21,"")+$F$5 -> 0.3 | G21: =E21 -> 19.574631 | H21: =IF(G21="","",G21-C21-($F$5)*G21) -> 13.702242 | I21: =IF(G21="","",H21/G21) -> 0.7 | J21: =IF(G21="","",H21-G21*$C$1) -> 9.7873157 | K21: =IFERROR(J21/G21,"") -> 0.5
A22: =A20+400 -> 905 | B22: BRIGADEIRO UNITÁRIO Quero | C22: =C20 -> 2.5251275 | D22: 1 | E22: =C22/(1-$C$1-$C$2-$F$6) -> 14.853691 | F22: =IFERROR(C22/G22,"")+$F$6 -> 0.3 | G22: =E22 -> 14.853691 | H22: =IF(G22="","",G22-C22-($F$6)*G22) -> 10.397584 | I22: =IF(G22="","",H22/G22) -> 0.7 | J22: =IF(G22="","",H22-G22*$C$1) -> 7.4268454 | K22: =IFERROR(J22/G22,"") -> 0.5
A23: =A20+1 -> 506 | B23: CAJUZINHO | D23: 1 | E23: =C23/(1-$C$1-$C$2-$F$4) -> 0 | F23: =IFERROR(C23/G23,"")+$F$4 -> #VALUE! | G23: =E23 -> 0 | H23: =IF(G23="","",G23-C23-($F$4)*G23) -> 0 | I23: =IF(G23="","",H23/G23) -> #DIV/0! | J23: =IF(G23="","",H23-G23*$C$1) -> 0 | K23: =IFERROR(J23/G23,"")
A24: =A23+200 -> 706 | B24: CAJUZINHO ifood | C24: =C23 -> 0 | D24: 1 | E24: =C24/(1-$C$1-$C$2-$F$5) -> 0 | F24: =IFERROR(C24/G24,"")+$F$5 -> #VALUE! | G24: =E24 -> 0 | H24: =IF(G24="","",G24-C24-($F$5)*G24) -> 0 | I24: =IF(G24="","",H24/G24) -> #DIV/0! | J24: =IF(G24="","",H24-G24*$C$1) -> 0 | K24: =IFERROR(J24/G24,"")
A25: =A23+400 -> 906 | B25: CAJUZINHO Quero | C25: =C23 -> 0 | D25: 1 | E25: =C25/(1-$C$1-$C$2-$F$6) -> 0 | F25: =IFERROR(C25/G25,"")+$F$6 -> #VALUE! | G25: =E25 -> 0 | H25: =IF(G25="","",G25-C25-($F$6)*G25) -> 0 | I25: =IF(G25="","",H25/G25) -> #DIV/0! | J25: =IF(G25="","",H25-G25*$C$1) -> 0 | K25: =IFERROR(J25/G25,"")
A26: =A23+1 -> 507 | B26: BEIJINHO | C26: =BEIJINHO!C4 -> 13 | D26: 1 | E26: =C26/(1-$C$1-$C$2-$F$4) -> 51.875499 | F26: =IFERROR(C26/G26,"")+$F$4 -> 0.3 | G26: =E26 -> 51.875499 | H26: =IF(G26="","",G26-C26-($F$4)*G26) -> 36.312849 | I26: =IF(G26="","",H26/G26) -> 0.7 | J26: =IF(G26="","",H26-G26*$C$1) -> 25.937749 | K26: =IFERROR(J26/G26,"") -> 0.5
A27: =A26+200 -> 707 | B27: BEIJINHO ifood | C27: =C26 -> 13 | D27: 1 | E27: =C27/(1-$C$1-$C$2-$F$5) -> 100.77519 | F27: =IFERROR(C27/G27,"")+$F$5 -> 0.3 | G27: =E27 -> 100.77519 | H27: =IF(G27="","",G27-C27-($F$5)*G27) -> 70.542636 | I27: =IF(G27="","",H27/G27) -> 0.7 | J27: =IF(G27="","",H27-G27*$C$1) -> 50.387597 | K27: =IFERROR(J27/G27,"") -> 0.5
A28: =A26+400 -> 907 | B28: BEIJINHO Quero | C28: =C26 -> 13 | D28: 1 | E28: =C28/(1-$C$1-$C$2-$F$6) -> 76.470588 | F28: =IFERROR(C28/G28,"")+$F$6 -> 0.3 | G28: =E28 -> 76.470588 | H28: =IF(G28="","",G28-C28-($F$6)*G28) -> 53.529412 | I28: =IF(G28="","",H28/G28) -> 0.7 | J28: =IF(G28="","",H28-G28*$C$1) -> 38.235294 | K28: =IFERROR(J28/G28,"") -> 0.5
A29: =A26+1 -> 508 | B29: ALFAJOR | C29: =ALFAJOR!C4 -> 13 | D29: 1 | E29: =C29/(1-$C$1-$C$2-$F$4) -> 51.875499 | F29: =IFERROR(C29/G29,"")+$F$4 -> 0.3 | G29: =E29 -> 51.875499 | H29: =IF(G29="","",G29-C29-($F$4)*G29) -> 36.312849 | I29: =IF(G29="","",H29/G29) -> 0.7 | J29: =IF(G29="","",H29-G29*$C$1) -> 25.937749 | K29: =IFERROR(J29/G29,"") -> 0.5
A30: =A29+200 -> 708 | B30: ALFAJOR ifood | C30: =C29 -> 13 | D30: 1 | E30: =C30/(1-$C$1-$C$2-$F$5) -> 100.77519 | F30: =IFERROR(C30/G30,"")+$F$5 -> 0.3 | G30: =E30 -> 100.77519 | H30: =IF(G30="","",G30-C30-($F$5)*G30) -> 70.542636 | I30: =IF(G30="","",H30/G30) -> 0.7 | J30: =IF(G30="","",H30-G30*$C$1) -> 50.387597 | K30: =IFERROR(J30/G30,"") -> 0.5
A31: =A29+400 -> 908 | B31: ALFAJOR Quero | C31: =C29 -> 13 | D31: 1 | E31: =C31/(1-$C$1-$C$2-$F$6) -> 76.470588 | F31: =IFERROR(C31/G31,"")+$F$6 -> 0.3 | G31: =E31 -> 76.470588 | H31: =IF(G31="","",G31-C31-($F$6)*G31) -> 53.529412 | I31: =IF(G31="","",H31/G31) -> 0.7 | J31: =IF(G31="","",H31-G31*$C$1) -> 38.235294 | K31: =IFERROR(J31/G31,"") -> 0.5
A32: =A29+1 -> 509 | B32: PALHA ITALIANA | C32: ='PALHA ITALIANNA'!C4 -> 13 | D32: 1 | E32: =C32/(1-$C$1-$C$2-$F$4) -> 51.875499 | F32: =IFERROR(C32/G32,"")+$F$4 -> 0.3 | G32: =E32 -> 51.875499 | H32: =IF(G32="","",G32-C32-($F$4)*G32) -> 36.312849 | I32: =IF(G32="","",H32/G32) -> 0.7 | J32: =IF(G32="","",H32-G32*$C$1) -> 25.937749 | K32: =IFERROR(J32/G32,"") -> 0.5
A33: =A32+200 -> 709 | B33: PALHA ITALIANA ifood | C33: =C32 -> 13 | D33: 1 | E33: =C33/(1-$C$1-$C$2-$F$5) -> 100.77519 | F33: =IFERROR(C33/G33,"")+$F$5 -> 0.3 | G33: =E33 -> 100.77519 | H33: =IF(G33="","",G33-C33-($F$5)*G33) -> 70.542636 | I33: =IF(G33="","",H33/G33) -> 0.7 | J33: =IF(G33="","",H33-G33*$C$1) -> 50.387597 | K33: =IFERROR(J33/G33,"") -> 0.5
A34: =A32+400 -> 909 | B34: PALHA ITALIANA Quero | C34: =C32 -> 13 | D34: 1 | E34: =C34/(1-$C$1-$C$2-$F$6) -> 76.470588 | F34: =IFERROR(C34/G34,"")+$F$6 -> 0.3 | G34: =E34 -> 76.470588 | H34: =IF(G34="","",G34-C34-($F$6)*G34) -> 53.529412 | I34: =IF(G34="","",H34/G34) -> 0.7 | J34: =IF(G34="","",H34-G34*$C$1) -> 38.235294 | K34: =IFERROR(J34/G34,"") -> 0.5
A35: =A32+1 -> 510 | B35: EMPADA DE FRANGO | C35: ='EMPADA DE FRANGO'!C4:D4 -> 13 | D35: 1 | E35: =C35/(1-$C$1-$C$2-$F$4) -> 51.875499 | F35: =IFERROR(C35/G35,"")+$F$4 -> 0.3 | G35: =E35 -> 51.875499 | H35: =IF(G35="","",G35-C35-($F$4)*G35) -> 36.312849 | I35: =IF(G35="","",H35/G35) -> 0.7 | J35: =IF(G35="","",H35-G35*$C$1) -> 25.937749 | K35: =IFERROR(J35/G35,"") -> 0.5
A36: =A35+200 -> 710 | B36: EMPADA DE FRANGO ifood | C36: =C35 -> 13 | D36: 1 | E36: =C36/(1-$C$1-$C$2-$F$5) -> 100.77519 | F36: =IFERROR(C36/G36,"")+$F$5 -> 0.3 | G36: =E36 -> 100.77519 | H36: =IF(G36="","",G36-C36-($F$5)*G36) -> 70.542636 | I36: =IF(G36="","",H36/G36) -> 0.7 | J36: =IF(G36="","",H36-G36*$C$1) -> 50.387597 | K36: =IFERROR(J36/G36,"") -> 0.5
A37: =A35+400 -> 910 | B37: EMPADA DE FRANGO Quero | C37: =C35 -> 13 | D37: 1 | E37: =C37/(1-$C$1-$C$2-$F$6) -> 76.470588 | F37: =IFERROR(C37/G37,"")+$F$6 -> 0.3 | G37: =E37 -> 76.470588 | H37: =IF(G37="","",G37-C37-($F$6)*G37) -> 53.529412 | I37: =IF(G37="","",H37/G37) -> 0.7 | J37: =IF(G37="","",H37-G37*$C$1) -> 38.235294 | K37: =IFERROR(J37/G37,"") -> 0.5
A38: =A35+1 -> 511 | B38: QUICHE DE FRANGO | C38: ='QUICHE DE FRANGO'!C4:D4 -> 13 | D38: 1 | E38: =C38/(1-$C$1-$C$2-$F$4) -> 51.875499 | F38: =IFERROR(C38/G38,"")+$F$4 -> 0.3 | G38: =E38 -> 51.875499 | H38: =IF(G38="","",G38-C38-($F$4)*G38) -> 36.312849 | I38: =IF(G38="","",H38/G38) -> 0.7 | J38: =IF(G38="","",H38-G38*$C$1) -> 25.937749 | K38: =IFERROR(J38/G38,"") -> 0.5
A39: =A38+200 -> 711 | B39: QUICHE DE FRANGO ifood | C39: =C38 -> 13 | D39: 1 | E39: =C39/(1-$C$1-$C$2-$F$5) -> 100.77519 | F39: =IFERROR(C39/G39,"")+$F$5 -> 0.3 | G39: =E39 -> 100.77519 | H39: =IF(G39="","",G39-C39-($F$5)*G39) -> 70.542636 | I39: =IF(G39="","",H39/G39) -> 0.7 | J39: =IF(G39="","",H39-G39*$C$1) -> 50.387597 | K39: =IFERROR(J39/G39,"") -> 0.5
A40: =A38+400 -> 911 | B40: QUICHE DE FRANGO Quero | C40: =C38 -> 13 | D40: 1 | E40: =C40/(1-$C$1-$C$2-$F$6) -> 76.470588 | F40: =IFERROR(C40/G40,"")+$F$6 -> 0.3 | G40: =E40 -> 76.470588 | H40: =IF(G40="","",G40-C40-($F$6)*G40) -> 53.529412 | I40: =IF(G40="","",H40/G40) -> 0.7 | J40: =IF(G40="","",H40-G40*$C$1) -> 38.235294 | K40: =IFERROR(J40/G40,"") -> 0.5
...

Sheet ListaIngredientes
A1: Objetivo | C1: Lista de I N G R E D I E N T E S
A2: Data de atualização | C2: 44281 | E2: Qt | F2: =COUNT(Tabela2[Cod]) -> 155
A4: Cod | B4: Descrição do Produto | C4: unidade | D4: fração | E4: Preço | F4: Preço por(g)
A5: 102 | B5: Ovos Branco | C5: duzia | D5: 12 | E5: 20 | F5: =IFERROR(E5/D5,"") -> 1.6666667
A6: =A5+1 -> 103 | B6: Leite condensado | C6: ml | D6: 400 | E6: 18 | F6: =IFERROR(E6/D6,"") -> 0.045
A7: =A6+1 -> 104 | B7: Leite Integral | C7: ml | D7: 1000 | E7: 12 | F7: =IFERROR(E7/D7,"") -> 0.012
A8: =A7+1 -> 105 | B8: Bananas | C8: duzias | D8: 12 | E8: 6 | F8: =IFERROR(E8/D8,"") -> 0.5
A9: =A8+1 -> 106 | B9: Colorau | C9: g | D9: 100 | E9: 2 | F9: =IFERROR(E9/D9,"") -> 0.02
A10: =A9+1 -> 107 | B10: Agua mineral | C10: ml | D10: 500 | E10: 23.45 | F10: =IFERROR(E10/D10,"") -> 0.0469
A11: =A10+1 -> 108 | B11: CANELA | C11: KG | D11: 1000 | E11: 55 | F11: 0.055
A12: =A11+1 -> 109 | B12: CASTANHA DO PARÁ | C12: KG | D12: 1000 | E12: 35 | F12: =IFERROR(E12/D12,"") -> 0.035
A13: =A12+1 -> 110 | B13: CASTANHA DE CAJU | C13: KG | D13: 1000 | E13: 35 | F13: =IFERROR(E13/D13,"") -> 0.035
A14: =A13+1 -> 111 | B14: azeite | C14: ml | D14: 500 | E14: 23 | F14: =IFERROR(E14/D14,"") -> 0.046
A15: =A14+1 -> 112 | B15: farinha de arroz | C15: kg | D15: 1000 | E15: 12 | F15: =IFERROR(E15/D15,"") -> 0.012
A16: =A15+1 -> 113 | B16: polvilho doce | C16: kg | D16: 1000 | E16: 10 | F16: =IFERROR(E16/D16,"") -> 0.01
A17: =A16+1 -> 114 | B17: fecula | C17: kg | D17: 1000 | E17: 10 | F17: 0.01 | J17: =J16+1 -> 1 | K17: CAIXA MEIO OVO 100G | L17: U | M17: 1 | N17: 6.19 | O17: =IFERROR(N17/M17,"") -> 6.19
A18: =A17+1 -> 115 | B18: CAMARÃO | C18: KG | D18: 1000 | E18: 65 | F18: 0.065 | J18: CAIXA OVO 100G | K18: u | L18: 30 | M18: 5.8 | N18: =IFERROR(M18/L18,"") -> 0.19333333
A19: =A18+1 -> 116 | B19: CARNE SECA | C19: KG | D19: 500 | E19: 27.5 | F19: 0.027 | J19: caixa ovo de colher | K19: u | L19: 1 | M19: 5.19 | N19: 5.19
A20: =A19+1 -> 117 | B20: BANANA DA TERRA | C20: U | D20: 1 | E20: 1 | F20: 1 | J20: caixa ovo de colher | K20: u | L20: 2 | M20: 5.19
A21: =A20+1 -> 118 | B21: QUEIJO MUSSARELA 0 LACTOSE | C21: KG | D21: 1000 | E21: 49.9 | F21: 0.049 | J21: caixa ovo duplo | K21: u | L21: 3 | M21: 4.79 | N21: =IFERROR(M21/L21,"") -> 1.5966667
A22: =A21+1 -> 119 | B22: berinjela | C22: u | D22: 3 | E22: 5 | F22: 1.66 | J22: caixa ovo trio | K22: u | L22: 1 | M22: 4.05 | N22: =IFERROR(M22/L22,"") -> 4.05
A23: =A22+1 -> 120 | B23: embalagem lasanha | C23: u | D23: 5 | E23: 2.65 | F23: 0.53 | J23: caixa tie dye | K23: u | L23: 1 | M23: 5.19 | N23: 5.19
A24: =A23+1 -> 121 | B24: embalagem marmita | C24: u | D24: 25 | E24: 23.5 | F24: 0.94 | J24: cesta grande | K24: u | L24: 2 | M24: 6.49 | N24: 12.98
A25: =A24+1 -> 122 | B25: CARNE PATINHO | C25: KG | D25: 1000 | E25: 33 | F25: 0.033 | J25: cesta madeira | K25: u | L25: 1 | M25: 22 | N25: =IFERROR(M25/L25,"") -> 22
A26: =A25+1 -> 123 | B26: BANANA PRATA | C26: U | D26: 4 | E26: 2 | F26: 0.5 | J26: coelho pelucia | K26: u | L26: 1 | M26: 16.9 | N26: =IFERROR(M26/L26,"") -> 16.9
A27: =A26+1 -> 124 | B27: BACON | C27: KG | D27: 1000 | E27: 31.9 | F27: =IFERROR(E27/D27,"") -> 0.0319 | J27: coelho pelucia | K27: u | L27: 1 | M27: 22.9 | N27: =IFERROR(M27/L27,"") -> 22.9
A28: =A27+1 -> 125 | J28: cx encanto | K28: u | L28: 1 | M28: 6.67 | N28: =IFERROR(M28/L28,"") -> 6.67
A29: =A28+1 -> 126 | B29: CHOCOLTE BRANCO | C29: KG | D29: 1000 | E29: 159.9 | F29: 0.159 | J29: cx gourmet ovo | K29: u | L29: 4 | M29: 4.39 | N29: =IFERROR(M29/L29,"") -> 1.0975
A30: =A29+1 -> 127 | B30: CHOCOLATE 70% | C30: KG | D30: 1000 | E30: 102 | F30: =IFERROR(E30/D30,"") -> 0.102 | J30: fita espuma | K30: u | L30: 1 | M30: 5.7 | N30: =IFERROR(M30/L30,"") -> 5.7
A31: =A30+1 -> 128 | B31: coco fino | C31: kg | D31: 1000 | E31: 40 | F31: =IFERROR(E31/D31,"") -> 0.04 | J31: fita tnt | K31: u | L31: 1 | M31: 6.89 | N31: 6.89
A32: =A31+1 -> 129 | B32: coco flococo | C32: kg | D32: 100 | E32: 3.99 | F32: =IFERROR(E32/D32,"") -> 0.0399 | J32: folha chumbo | K32: u | L32: 1 | M32: 1.05 | N32: =IFERROR(M32/L32,"") -> 1.05
A33: =A32+1 -> 130 | J33: forma coelho | K33: u | L33: 1 | M33: 5.49 | N33: 5.49
A34: =A33+1 -> 131 | J34: kit de bico | K34: u | L34: 1 | M34: 9.9 | N34: =IFERROR(M34/L34,"") -> 9.9
A35: =A34+1 -> 132 | B35: copo açaí | C35: u | D35: 50 | E35: 8.49 | F35: =IFERROR(E35/D35,"") -> 0.1698 | J35: LATA PALHA ITALIANA | K35: U | L35: 1 | M35: 1.59 | N35: =IFERROR(M35/L35,"") -> 1.59
A36: =A35+1 -> 133 | B36: suporte para torta | C36: u | D36: 1 | E36: 4 | F36: 4 | J36: lata pra ovo | K36: u | L36: 1 | M36: 9.39 | N36: 9.39
A37: =A36+1 -> 134 | B37: copo bolha | C37: u | D37: 10 | E37: 8.49 | F37: =IFERROR(E37/D37,"") -> 0.849 | J37: mine colher | K37: pct | L37: 1 | M37: 8.39 | N37: =IFERROR(M37/L37,"") -> 8.39
A38: =A37+1 -> 135 | B38: ISOPOR DE PIZZA REDONDA | C38: u | D38: 10 | E38: 2.99 | F38: 0.29 | J38: ninho coelho | K38: u | L38: 2 | M38: 4.99 | N38: 9.98
A39: =A38+1 -> 136 | B39: embalagem retangular torta g630 | C39: u | D39: 10 | E39: 8.9 | F39: =IFERROR(E39/D39,"") -> 0.89 | J39: panelinha | K39: pc | L39: 1 | M39: 10.15 | N39: =IFERROR(M39/L39,"") -> 10.15
A40: =A39+1 -> 137 | B40: copo quadrado brigadeiro duo | C40: u | D40: 10 | E40: 5.89 | F40: 0.58 | J40: papel glasspel | K40: u | L40: 1 | M40: 2.99 | N40: 2.99
A41: =A40+1 -> 138 | B41: CHIPS DE COCO | C41: KG | D41: 1000 | E41: 65 | F41: =IFERROR(E41/D41,"") -> 0.065 | J41: papel manteiga | K41: u | L41: 1 | M41: 4.59 | N41: 4.59
...

Sheet Violino
A1: cod | B1: 501 | C1: =VLOOKUP(B1,PRODUTOS!$A$7:$E$204,2,FALSE) -> P A S T E L | E1: =C3 -> 4.7896 | G1: SOBREMESA/DOCE | J1: 1ª PARTE - CALCULAR O TOTAL DO CUSTO | P1: C U S T O
A2: Despesas Fixas/Variáveis | C2: =L10+L11 -> 0.2 | E2: Preço Venda Unit | G2: =IFERROR(C3/(1-C2-C5),"") -> 9.5792
A3: Custo Unitário | C3: =IFERROR(C7/C4,"") -> 4.7896 | E3: Luro s/Venda | G3: =G2*C5 -> 2.87376
A4: Quantidade Produzida | C4: 6 | E4: Preço Concorrencia | G4: =G2 -> 9.5792 | L4: =C7 -> 28.7376
A5: Lucro s/Venda | C5: =L12 -> 0.3 | E5: Lucro Praticado | G5: =1-C3/G4-C2 -> 0.3 | J5: INFORMAR QUNATAS UNIDADES SERÃO PRODUZIDAS
A6: Preço ZERO | E6: =C3/(1-C2) -> 5.987
A7: Gasto Total | C7: =H29 -> 28.7376 | E7: Lucro Praticado | G7: =G5*G4 -> 2.87376 | L7: =C4 -> 6
A8: cod Prod | B8: Descrição ingredientes | D8: unid | E8: quantiadade | F8: valor $ | H8: Subtotal | J8: CALCULAR O CUSTO UNITÁRIO DE CADA PASTEL
A9: 102 | B9: =IFERROR(VLOOKUP(A9,ListaIngredientes!$A$5:$F$155,2,FALSE),"") -> Ovos Branco | D9: =IFERROR(VLOOKUP(A9,Tabela2[],3,FALSE),"") -> duzia | E9: 12 | F9: =IFERROR(VLOOKUP(A9,ListaIngredientes!$A$5:$F$155,6,FALSE),"") -> 1.6666667 | H9: =IFERROR(E9*F9,"") -> 20 | L9: =L4/L7 -> 4.7896
A10: 103 | B10: =IFERROR(VLOOKUP(A10,ListaIngredientes!$A$5:$F$155,2,FALSE),"") -> Leite condensado | D10: =IFERROR(VLOOKUP(A10,Tabela2[],3,FALSE),"") -> ml | E10: 50 | F10: =IFERROR(VLOOKUP(A10,ListaIngredientes!$A$5:$F$155,6,FALSE),"") -> 0.045 | H10: =IFERROR(E10*F10,"") -> 2.25 | J10: Despesas Fixas | L10: 0.12 | M10: O sistema gestão do preço calcula, através dos parâmateros feitos por SANDRO
A11: 104 | B11: =IFERROR(VLOOKUP(A11,ListaIngredientes!$A$5:$F$155,2,FALSE),"") -> Leite Integral | D11: =IFERROR(VLOOKUP(A11,Tabela2[],3,FALSE),"") -> ml | E11: 225 | F11: =IFERROR(VLOOKUP(A11,ListaIngredientes!$A$5:$F$155,6,FALSE),"") -> 0.012 | H11: =IFERROR(E11*F11,"") -> 2.7 | J11: Despesas Variáves | L11: 0.08
A12: 105 | B12: =IFERROR(VLOOKUP(A12,ListaIngredientes!$A$5:$F$155,2,FALSE),"") -> Bananas | D12: =IFERROR(VLOOKUP(A12,Tabela2[],3,FALSE),"") -> duzias | E12: 6 | F12: =IFERROR(VLOOKUP(A12,ListaIngredientes!$A$5:$F$155,6,FALSE),"") -> 0.5 | H12: =IFERROR(E12*F12,"") -> 3 | J12: lucro | L12: 0.3 | M12: Este varia
A13: 106 | B13: =IFERROR(VLOOKUP(A13,ListaIngredientes!$A$5:$F$155,2,FALSE),"") -> Colorau | D13: =IFERROR(VLOOKUP(A13,Tabela2[],3,FALSE),"") -> g | E13: 30 | F13: =IFERROR(VLOOKUP(A13,ListaIngredientes!$A$5:$F$155,6,FALSE),"") -> 0.02 | H13: =IFERROR(E13*F13,"") -> 0.6 | J13: soma | L13: =SUM(L10:L12) -> 0.5
A14: 107 | B14: =IFERROR(VLOOKUP(A14,ListaIngredientes!$A$5:$F$155,2,FALSE),"") -> Agua mineral | D14: =IFERROR(VLOOKUP(A14,Tabela2[],3,FALSE),"") -> ml | E14: 4 | F14: =IFERROR(VLOOKUP(A14,ListaIngredientes!$A$5:$F$155,6,FALSE),"") -> 0.0469 | H14: =IFERROR(E14*F14,"") -> 0.1876 | J14: Cálculo do Preço de Venda
B15: =IFERROR(VLOOKUP(A15,ListaIngredientes!$A$5:$F$155,2,FALSE),"") | D15: =IFERROR(VLOOKUP(A15,Tabela2[],3,FALSE),"") | F15: =IFERROR(VLOOKUP(A15,ListaIngredientes!$A$5:$F$155,6,FALSE),"") | H15: =IFERROR(E15*F15,"")
B16: =IFERROR(VLOOKUP(A16,ListaIngredientes!$A$5:$F$155,2,FALSE),"") | D16: =IFERROR(VLOOKUP(A16,Tabela2[],3,FALSE),"") | F16: =IFERROR(VLOOKUP(A16,ListaIngredientes!$A$5:$F$155,6,FALSE),"") | H16: =IFERROR(E16*F16,"") | J16: fórmula | K16: =preco custo/(1-soma)
B17: =IFERROR(VLOOKUP(A17,ListaIngredientes!$A$5:$F$155,2,FALSE),"") | D17: =IFERROR(VLOOKUP(A17,Tabela2[],3,FALSE),"") | F17: =IFERROR(VLOOKUP(A17,ListaIngredientes!$A$5:$F$155,6,FALSE),"") | H17: =IFERROR(E17*F17,"") | K17: =L9/(1-L13) -> 9.5792 | O17: C=preço de custo
B18: =IFERROR(VLOOKUP(A18,ListaIngredientes!$A$5:$F$155,2,FALSE),"") | D18: =IFERROR(VLOOKUP(A18,Tabela2[],3,FALSE),"") | F18: =IFERROR(VLOOKUP(A18,ListaIngredientes!$A$5:$F$155,6,FALSE),"") | H18: =IFERROR(E18*F18,"") | J18: sonhos de ediberto | O18: V= preço da venda conc
B19: =IFERROR(VLOOKUP(A19,ListaIngredientes!$A$5:$F$155,2,FALSE),"") | D19: =IFERROR(VLOOKUP(A19,Tabela2[],3,FALSE),"") | F19: =IFERROR(VLOOKUP(A19,ListaIngredientes!$A$5:$F$155,6,FALSE),"") | H19: =IFERROR(E19*F19,"") | J19: Ele ter um preço do concorrente | N19: =N23 -> 5.987
B20: =IFERROR(VLOOKUP(A20,ListaIngredientes!$A$5:$F$155,2,FALSE),"") | D20: =IFERROR(VLOOKUP(A20,Tabela2[],3,FALSE),"") | F20: =IFERROR(VLOOKUP(A20,ListaIngredientes!$A$5:$F$155,6,FALSE),"") | H20: =IFERROR(E20*F20,"") | J20: fórmula | K20: "=1-C/V-DF-DV
B21: =IFERROR(VLOOKUP(A21,ListaIngredientes!$A$5:$F$155,2,FALSE),"") | D21: =IFERROR(VLOOKUP(A21,Tabela2[],3,FALSE),"") | F21: =IFERROR(VLOOKUP(A21,ListaIngredientes!$A$5:$F$155,6,FALSE),"") | H21: =IFERROR(E21*F21,"") | K21: =1-L9/N19-L10-L11 -> 0
B22: =IFERROR(VLOOKUP(A22,ListaIngredientes!$A$5:$F$155,2,FALSE),"") | D22: =IFERROR(VLOOKUP(A22,Tabela2[],3,FALSE),"") | F22: =IFERROR(VLOOKUP(A22,ListaIngredientes!$A$5:$F$155,6,FALSE),"") | H22: =IFERROR(E22*F22,"") | J22: ponto de Equilibrio
B23: =IFERROR(VLOOKUP(A23,ListaIngredientes!$A$5:$F$155,2,FALSE),"") | D23: =IFERROR(VLOOKUP(A23,Tabela2[],3,FALSE),"") | F23: =IFERROR(VLOOKUP(A23,ListaIngredientes!$A$5:$F$155,6,FALSE),"") | H23: =IFERROR(E23*F23,"") | J23: DF | K23: =L10 -> 0.12 | L23: =K23*$K$17 -> 1.149504 | M23: PV | N23: =L25/(1-K23-K24) -> 5.987
B24: =IFERROR(VLOOKUP(A24,ListaIngredientes!$A$5:$F$155,2,FALSE),"") | D24: =IFERROR(VLOOKUP(A24,Tabela2[],3,FALSE),"") | F24: =IFERROR(VLOOKUP(A24,ListaIngredientes!$A$5:$F$155,6,FALSE),"") | H24: =IFERROR(E24*F24,"") | J24: DV | K24: =L11 -> 0.08 | L24: =K24*$K$17 -> 0.766336 | M24: PV =C/(1-DF-DV) | O24: PE
B25: =IFERROR(VLOOKUP(A25,ListaIngredientes!$A$5:$F$155,2,FALSE),"") | D25: =IFERROR(VLOOKUP(A25,Tabela2[],3,FALSE),"") | F25: =IFERROR(VLOOKUP(A25,ListaIngredientes!$A$5:$F$155,6,FALSE),"") | H25: =IFERROR(E25*F25,"") | J25: C | K25: =L25/K17 -> 0.5 | L25: =L9 -> 4.7896
B26: =IFERROR(VLOOKUP(A26,ListaIngredientes!$A$5:$F$155,2,FALSE),"") | D26: =IFERROR(VLOOKUP(A26,Tabela2[],3,FALSE),"") | F26: =IFERROR(VLOOKUP(A26,ListaIngredientes!$A$5:$F$155,6,FALSE),"") | H26: =IFERROR(E26*F26,"") | J26: L | K26: 0.2 | L26: =K26*$K$17 -> 1.91584
B27: =IFERROR(VLOOKUP(A27,ListaIngredientes!$A$5:$F$155,2,FALSE),"") | D27: =IFERROR(VLOOKUP(A27,Tabela2[],3,FALSE),"") | F27: =IFERROR(VLOOKUP(A27,ListaIngredientes!$A$5:$F$155,6,FALSE),"") | H27: =IFERROR(E27*F27,"") | J27: Outro sonho de Ediberto
B28: =IFERROR(VLOOKUP(A28,ListaIngredientes!$A$5:$F$155,2,FALSE),"") | D28: =IFERROR(VLOOKUP(A28,Tabela2[],3,FALSE),"") | F28: =IFERROR(VLOOKUP(A28,ListaIngredientes!$A$5:$F$155,6,FALSE),"") | H28: =IFERROR(E28*F28,"") | K28: D R E
F29: soma | H29: =SUM(H9:H28) -> 28.7376 | J29: Preço de Venda | M29: =K17 -> 9.5792
J30: Preço do Custo | M30: =-L9 -> -4.7896
J31: DF | L31: =L10 -> 0.12 | M31: =-L31*M29 -> -1.149504
J32: DV | L32: =L11 -> 0.08 | M32: =-L32*M29 -> -0.766336
J34: lucro | M34: =SUM(M29:M33) -> 2.87376 | N34: =M34/M29 -> 0.3

Sheet BOLO GELADO ABACAXI
A1: cod | B1: 502 | C1: =VLOOKUP(B1,PRODUTOS!$A$7:$E$204,2,FALSE) -> BOLO GELADO ABACAXI | E1: =C3 -> 99.690995 | G1: SOBREMESA/DOCE
A2: Despesas Fixas | C2: 0.2 | E2: Preço Venda Unit | G2: =IFERROR(C3/(1-C2-C5),"") -> 332.30332
A3: Custo Unitário | C3: =IFERROR(C6/C4,"") -> 99.690995 | E3: Luro s/Venda | G3: =G2*C5 -> 166.15166
A4: Quantidade Produzida | C4: 6 | E4: Preço Praticado | G4: 15
A5: Lucro s/Venda | C5: 0.5 | E5: Lucro Praticado | G5: =1-C3/G4-C2 -> -5.8460663
A6: Gasto Total | C6: =H28 -> 598.14597 | E6: Lucro Praticado | G6: =G5*G4 -> -87.690995
A7: cod Prod | B7: Descrição ingredientes | D7: unid | E7: quantiadade | F7: valor $ | H7: Subtotal
A8: 101 | B8: =IFERROR(VLOOKUP(A8,ListaIngredientes!$A$5:$F$155,2,FALSE),"") | D8: =IFERROR(VLOOKUP(A8,Tabela2[],3,FALSE),"") | E8: 6 | F8: =IFERROR(VLOOKUP(A8,ListaIngredientes!$A$5:$F$155,6,FALSE),"") | H8: =IFERROR(E8*F8,"")
A9: 100 | B9: =IFERROR(VLOOKUP(A9,ListaIngredientes!$A$5:$F$155,2,FALSE),"") | D9: =IFERROR(VLOOKUP(A9,Tabela2[],3,FALSE),"") | E9: 0.5 | F9: =IFERROR(VLOOKUP(A9,ListaIngredientes!$A$5:$F$155,6,FALSE),"") | H9: =IFERROR(E9*F9,"")
A10: 188 | B10: =IFERROR(VLOOKUP(A10,ListaIngredientes!$A$5:$F$155,2,FALSE),"") -> LATA PALHA ITALIANA | D10: =IFERROR(VLOOKUP(A10,Tabela2[],3,FALSE),"") -> U | E10: 350 | F10: =IFERROR(VLOOKUP(A10,ListaIngredientes!$A$5:$F$155,6,FALSE),"") -> 1.59 | H10: =IFERROR(E10*F10,"") -> 556.5
A11: 139 | B11: =IFERROR(VLOOKUP(A11,ListaIngredientes!$A$5:$F$155,2,FALSE),"") -> cravo da india | D11: =IFERROR(VLOOKUP(A11,Tabela2[],3,FALSE),"") -> g | E11: 200 | F11: =IFERROR(VLOOKUP(A11,ListaIngredientes!$A$5:$F$155,6,FALSE),"") -> 0.00058823529 | H11: =IFERROR(E11*F11,"") -> 0.11764706
A12: 126 | B12: =IFERROR(VLOOKUP(A12,ListaIngredientes!$A$5:$F$155,2,FALSE),"") -> CHOCOLTE BRANCO | D12: =IFERROR(VLOOKUP(A12,Tabela2[],3,FALSE),"") -> KG | E12: 110 | F12: =IFERROR(VLOOKUP(A12,ListaIngredientes!$A$5:$F$155,6,FALSE),"") -> 0.159 | H12: =IFERROR(E12*F12,"") -> 17.49
A13: 203 | B13: =IFERROR(VLOOKUP(A13,ListaIngredientes!$A$5:$F$155,2,FALSE),"") -> 0 | D13: =IFERROR(VLOOKUP(A13,Tabela2[],3,FALSE),"") -> 0 | E13: 3 | F13: =IFERROR(VLOOKUP(A13,ListaIngredientes!$A$5:$F$155,6,FALSE),"") -> 0 | H13: =IFERROR(E13*F13,"") -> 0
A14: 230 | B14: =IFERROR(VLOOKUP(A14,ListaIngredientes!$A$5:$F$155,2,FALSE),"") -> 0 | D14: kg | E14: 105 | F14: =IFERROR(VLOOKUP(A14,ListaIngredientes!$A$5:$F$155,6,FALSE),"") -> 0.149 | H14: =IFERROR(E14*F14,"") -> 15.645
A15: 163 | B15: =IFERROR(VLOOKUP(A15,ListaIngredientes!$A$5:$F$155,2,FALSE),"") -> fermento biologico | D15: kg | E15: 11 | F15: =IFERROR(VLOOKUP(A15,ListaIngredientes!$A$5:$F$155,6,FALSE),"") -> 0.05512 | H15: =IFERROR(E15*F15,"") -> 0.60632
A16: 146 | B16: =IFERROR(VLOOKUP(A16,ListaIngredientes!$A$5:$F$155,2,FALSE),"") -> embalagem bolo de pote | D16: u | E16: 6 | F16: =IFERROR(VLOOKUP(A16,ListaIngredientes!$A$5:$F$155,6,FALSE),"") -> 0.599 | H16: =IFERROR(E16*F16,"") -> 3.594
A17: 202 | B17: =IFERROR(VLOOKUP(A17,ListaIngredientes!$A$5:$F$155,2,FALSE),"") -> 0 | D17: =IFERROR(VLOOKUP(A17,Tabela2[],3,FALSE),"") -> 0 | E17: 50 | F17: =IFERROR(VLOOKUP(A17,ListaIngredientes!$A$5:$F$155,6,FALSE),"") -> 0 | H17: =IFERROR(E17*F17,"") -> 0
A18: 156 | B18: =IFERROR(VLOOKUP(A18,ListaIngredientes!$A$5:$F$155,2,FALSE),"") -> embalagem quiche | D18: =IFERROR(VLOOKUP(A18,Tabela2[],3,FALSE),"") -> u | E18: 7 | F18: =IFERROR(VLOOKUP(A18,ListaIngredientes!$A$5:$F$155,6,FALSE),"") -> 0.599 | H18: =IFERROR(E18*F18,"") -> 4.193
B19: =IFERROR(VLOOKUP(A19,ListaIngredientes!$A$5:$F$155,2,FALSE),"") | D19: =IFERROR(VLOOKUP(A19,Tabela2[],3,FALSE),"") | F19: =IFERROR(VLOOKUP(A19,ListaIngredientes!$A$5:$F$155,6,FALSE),"") | H19: =IFERROR(E19*F19,"")
B20: =IFERROR(VLOOKUP(A20,ListaIngredientes!$A$5:$F$155,2,FALSE),"") | D20: =IFERROR(VLOOKUP(A20,Tabela2[],3,FALSE),"") | F20: =IFERROR(VLOOKUP(A20,ListaIngredientes!$A$5:$F$155,6,FALSE),"") | H20: =IFERROR(E20*F20,"")
B21: =IFERROR(VLOOKUP(A21,ListaIngredientes!$A$5:$F$155,2,FALSE),"") | D21: =IFERROR(VLOOKUP(A21,Tabela2[],3,FALSE),"") | F21: =IFERROR(VLOOKUP(A21,ListaIngredientes!$A$5:$F$155,6,FALSE),"") | H21: =IFERROR(E21*F21,"")
B22: =IFERROR(VLOOKUP(A22,ListaIngredientes!$A$5:$F$155,2,FALSE),"") | D22: =IFERROR(VLOOKUP(A22,Tabela2[],3,FALSE),"") | F22: =IFERROR(VLOOKUP(A22,ListaIngredientes!$A$5:$F$155,6,FALSE),"") | H22: =IFERROR(E22*F22,"")
B23: =IFERROR(VLOOKUP(A23,ListaIngredientes!$A$5:$F$155,2,FALSE),"") | D23: =IFERROR(VLOOKUP(A23,Tabela2[],3,FALSE),"") | F23: =IFERROR(VLOOKUP(A23,ListaIngredientes!$A$5:$F$155,6,FALSE),"") | H23: =IFERROR(E23*F23,"")
B24: =IFERROR(VLOOKUP(A24,ListaIngredientes!$A$5:$F$155,2,FALSE),"") | D24: =IFERROR(VLOOKUP(A24,Tabela2[],3,FALSE),"") | F24: =IFERROR(VLOOKUP(A24,ListaIngredientes!$A$5:$F$155,6,FALSE),"") | H24: =IFERROR(E24*F24,"")
B25: =IFERROR(VLOOKUP(A25,ListaIngredientes!$A$5:$F$155,2,FALSE),"") | D25: =IFERROR(VLOOKUP(A25,Tabela2[],3,FALSE),"") | F25: =IFERROR(VLOOKUP(A25,ListaIngredientes!$A$5:$F$155,6,FALSE),"") | H25: =IFERROR(E25*F25,"")
B26: =IFERROR(VLOOKUP(A26,ListaIngredientes!$A$5:$F$155,2,FALSE),"") | D26: =IFERROR(VLOOKUP(A26,Tabela2[],3,FALSE),"") | F26: =IFERROR(VLOOKUP(A26,ListaIngredientes!$A$5:$F$155,6,FALSE),"") | H26: =IFERROR(E26*F26,"")
B27: =IFERROR(VLOOKUP(A27,ListaIngredientes!$A$5:$F$155,2,FALSE),"") | D27: =IFERROR(VLOOKUP(A27,Tabela2[],3,FALSE),"") | F27: =IFERROR(VLOOKUP(A27,ListaIngredientes!$A$5:$F$155,6,FALSE),"") | H27: =IFERROR(E27*F27,"")
F28: soma | H28: =SUM(H8:H27) -> 598.14597

Sheet BRIG COLHER
A1: cod | B1: 504 | C1: =VLOOKUP(B1,PRODUTOS!$A$7:$E$204,2,FALSE) -> BRIGADEIRO DE COLHER | E1: =C3 -> 4.5661438 | G1: SOBREMESA/DOCE
A2: Despesas Fixas | C2: 0.2 | E2: Preço Venda Unit | G2: =IFERROR(C3/(1-C2-C5),"") -> 15.220479
A3: Custo Unitário | C3: =IFERROR(C6/C4,"") -> 4.5661438 | E3: Luro s/Venda | G3: =G2*C5 -> 7.6102397
A4: Quantidade Produzida | C4: 9 | E4: Preço Praticado | G4: 15
A5: Lucro s/Venda | C5: 0.5 | E5: Lucro Praticado | G5: =1-C3/G4-C2 -> 0.49559041
A6: Gasto Total | C6: =H28 -> 41.095294 | E6: Lucro Praticado | G6: =G5*G4 -> 7.4338562
A7: cod Prod | B7: Descrição ingredientes | D7: unid | E7: quantiadade | F7: valor $ | H7: Subtotal
A8: 101 | B8: =IFERROR(VLOOKUP(A8,ListaIngredientes!$A$5:$F$155,2,FALSE),"") | D8: =IFERROR(VLOOKUP(A8,Tabela2[],3,FALSE),"") | E8: 9 | F8: =IFERROR(VLOOKUP(A8,ListaIngredientes!$A$5:$F$155,6,FALSE),"") | H8: =IFERROR(E8*F8,"")
A9: 105 | B9: =IFERROR(VLOOKUP(A9,ListaIngredientes!$A$5:$F$155,2,FALSE),"") -> Bananas | D9: =IFERROR(VLOOKUP(A9,Tabela2[],3,FALSE),"") -> duzias | E9: 40 | F9: =IFERROR(VLOOKUP(A9,ListaIngredientes!$A$5:$F$155,6,FALSE),"") -> 0.5 | H9: =IFERROR(E9*F9,"") -> 20
A10: 125 | B10: =IFERROR(VLOOKUP(A10,ListaIngredientes!$A$5:$F$155,2,FALSE),"") -> 0 | D10: =IFERROR(VLOOKUP(A10,Tabela2[],3,FALSE),"") -> 0 | E10: 140 | F10: =IFERROR(VLOOKUP(A10,ListaIngredientes!$A$5:$F$155,6,FALSE),"") -> 0 | H10: =IFERROR(E10*F10,"") -> 0
A11: 139 | B11: =IFERROR(VLOOKUP(A11,ListaIngredientes!$A$5:$F$155,2,FALSE),"") -> cravo da india | D11: =IFERROR(VLOOKUP(A11,Tabela2[],3,FALSE),"") -> g | E11: 400 | F11: =IFERROR(VLOOKUP(A11,ListaIngredientes!$A$5:$F$155,6,FALSE),"") -> 0.00058823529 | H11: =IFERROR(E11*F11,"") -> 0.23529412
A12: 230 | B12: =IFERROR(VLOOKUP(A12,ListaIngredientes!$A$5:$F$155,2,FALSE),"") -> 0 | D12: kg | E12: 140 | F12: =IFERROR(VLOOKUP(A12,ListaIngredientes!$A$5:$F$155,6,FALSE),"") -> 0.149 | H12: =IFERROR(E12*F12,"") -> 20.86
A13: 143 | B13: =IFERROR(VLOOKUP(A13,ListaIngredientes!$A$5:$F$155,2,FALSE),"") -> 0 | D13: u | E13: 9 | F13: =IFERROR(VLOOKUP(A13,ListaIngredientes!$A$5:$F$155,6,FALSE),"") -> 0 | H13: =IFERROR(E13*F13,"") -> 0
B14: =IFERROR(VLOOKUP(A14,ListaIngredientes!$A$5:$F$155,2,FALSE),"") | F14: =IFERROR(VLOOKUP(A14,ListaIngredientes!$A$5:$F$155,6,FALSE),"") | H14: =IFERROR(E14*F14,"")
B15: =IFERROR(VLOOKUP(A15,ListaIngredientes!$A$5:$F$155,2,FALSE),"") | F15: =IFERROR(VLOOKUP(A15,ListaIngredientes!$A$5:$F$155,6,FALSE),"") | H15: =IFERROR(E15*F15,"")
B16: =IFERROR(VLOOKUP(A16,ListaIngredientes!$A$5:$F$155,2,FALSE),"") | F16: =IFERROR(VLOOKUP(A16,ListaIngredientes!$A$5:$F$155,6,FALSE),"") | H16: =IFERROR(E16*F16,"")
B17: =IFERROR(VLOOKUP(A17,ListaIngredientes!$A$5:$F$155,2,FALSE),"") | D17: =IFERROR(VLOOKUP(A17,Tabela2[],3,FALSE),"") | F17: =IFERROR(VLOOKUP(A17,ListaIngredientes!$A$5:$F$155,6,FALSE),"") | H17: =IFERROR(E17*F17,"")
B18: =IFERROR(VLOOKUP(A18,ListaIngredientes!$A$5:$F$155,2,FALSE),"") | D18: =IFERROR(VLOOKUP(A18,Tabela2[],3,FALSE),"") | F18: =IFERROR(VLOOKUP(A18,ListaIngredientes!$A$5:$F$155,6,FALSE),"") | H18: =IFERROR(E18*F18,"")
B19: =IFERROR(VLOOKUP(A19,ListaIngredientes!$A$5:$F$155,2,FALSE),"") | D19: =IFERROR(VLOOKUP(A19,Tabela2[],3,FALSE),"") | F19: =IFERROR(VLOOKUP(A19,ListaIngredientes!$A$5:$F$155,6,FALSE),"") | H19: =IFERROR(E19*F19,"")
B20: =IFERROR(VLOOKUP(A20,ListaIngredientes!$A$5:$F$155,2,FALSE),"") | D20: =IFERROR(VLOOKUP(A20,Tabela2[],3,FALSE),"") | F20: =IFERROR(VLOOKUP(A20,ListaIngredientes!$A$5:$F$155,6,FALSE),"") | H20: =IFERROR(E20*F20,"")
B21: =IFERROR(VLOOKUP(A21,ListaIngredientes!$A$5:$F$155,2,FALSE),"") | D21: =IFERROR(VLOOKUP(A21,Tabela2[],3,FALSE),"") | F21: =IFERROR(VLOOKUP(A21,ListaIngredientes!$A$5:$F$155,6,FALSE),"") | H21: =IFERROR(E21*F21,"")
B22: =IFERROR(VLOOKUP(A22,ListaIngredientes!$A$5:$F$155,2,FALSE),"") | D22: =IFERROR(VLOOKUP(A22,Tabela2[],3,FALSE),"") | F22: =IFERROR(VLOOKUP(A22,ListaIngredientes!$A$5:$F$155,6,FALSE),"") | H22: =IFERROR(E22*F22,"")
B23: =IFERROR(VLOOKUP(A23,ListaIngredientes!$A$5:$F$155,2,FALSE),"") | D23: =IFERROR(VLOOKUP(A23,Tabela2[],3,FALSE),"") | F23: =IFERROR(VLOOKUP(A23,ListaIngredientes!$A$5:$F$155,6,FALSE),"") | H23: =IFERROR(E23*F23,"")
B24: =IFERROR(VLOOKUP(A24,ListaIngredientes!$A$5:$F$155,2,FALSE),"") | D24: =IFERROR(VLOOKUP(A24,Tabela2[],3,FALSE),"") | F24: =IFERROR(VLOOKUP(A24,ListaIngredientes!$A$5:$F$155,6,FALSE),"") | H24: =IFERROR(E24*F24,"")
B25: =IFERROR(VLOOKUP(A25,ListaIngredientes!$A$5:$F$155,2,FALSE),"") | D25: =IFERROR(VLOOKUP(A25,Tabela2[],3,FALSE),"") | F25: =IFERROR(VLOOKUP(A25,ListaIngredientes!$A$5:$F$155,6,FALSE),"") | H25: =IFERROR(E25*F25,"")
B26: =IFERROR(VLOOKUP(A26,ListaIngredientes!$A$5:$F$155,2,FALSE),"") | D26: =IFERROR(VLOOKUP(A26,Tabela2[],3,FALSE),"") | F26: =IFERROR(VLOOKUP(A26,ListaIngredientes!$A$5:$F$155,6,FALSE),"") | H26: =IFERROR(E26*F26,"")
B27: =IFERROR(VLOOKUP(A27,ListaIngredientes!$A$5:$F$155,2,FALSE),"") | D27: =IFERROR(VLOOKUP(A27,Tabela2[],3,FALSE),"") | F27: =IFERROR(VLOOKUP(A27,ListaIngredientes!$A$5:$F$155,6,FALSE),"") | H27: =IFERROR(E27*F27,"")
F28: soma | H28: =SUM(H8:H27) -> 41.095294

Sheet BRIG UNITARIO
A1: cod | B1: 505 | C1: =VLOOKUP(B1,PRODUTOS!$A$7:$E$204,2,FALSE) -> BRIGADEIRO UNITÁRIO | E1: =C3 -> 2.5251275 | G1: SOBREMESA/DOCE
A2: Despesas Fixas | C2: 0.2 | E2: Preço Venda Unit | G2: =IFERROR(C3/(1-C2-C5),"") -> 8.4170915
A3: Custo Unitário | C3: =IFERROR(C6/C4,"") -> 2.5251275 | E3: Luro s/Venda | G3: =G2*C5 -> 4.2085458
A4: Quantidade Produzida | C4: 18 | E4: Preço Praticado | G4: 4
A5: Lucro s/Venda | C5: 0.5 | E5: Lucro Praticado | G5: =1-C3/G4-C2 -> 0.16871814
A6: Gasto Total | C6: =H28 -> 45.452294 | E6: Lucro Praticado | G6: =G5*G4 -> 0.67487255
A7: cod Prod | B7: Descrição ingredientes | D7: unid | E7: quantiadade | F7: valor $ | H7: Subtotal
A8: 101 | B8: =IFERROR(VLOOKUP(A8,ListaIngredientes!$A$5:$F$155,2,FALSE),"") | D8: =IFERROR(VLOOKUP(A8,Tabela2[],3,FALSE),"") | E8: 18 | F8: =IFERROR(VLOOKUP(A8,ListaIngredientes!$A$5:$F$155,6,FALSE),"") | H8: =IFERROR(E8*F8,"")
A9: 105 | B9: =IFERROR(VLOOKUP(A9,ListaIngredientes!$A$5:$F$155,2,FALSE),"") -> Bananas | D9: =IFERROR(VLOOKUP(A9,Tabela2[],3,FALSE),"") -> duzias | E9: 40 | F9: =IFERROR(VLOOKUP(A9,ListaIngredientes!$A$5:$F$155,6,FALSE),"") -> 0.5 | H9: =IFERROR(E9*F9,"") -> 20
A10: 125 | B10: =IFERROR(VLOOKUP(A10,ListaIngredientes!$A$5:$F$155,2,FALSE),"") -> 0 | D10: =IFERROR(VLOOKUP(A10,Tabela2[],3,FALSE),"") -> 0 | E10: 140 | F10: =IFERROR(VLOOKUP(A10,ListaIngredientes!$A$5:$F$155,6,FALSE),"") -> 0 | H10: =IFERROR(E10*F10,"") -> 0
A11: 139 | B11: =IFERROR(VLOOKUP(A11,ListaIngredientes!$A$5:$F$155,2,FALSE),"") -> cravo da india | D11: =IFERROR(VLOOKUP(A11,Tabela2[],3,FALSE),"") -> g | E11: 400 | F11: =IFERROR(VLOOKUP(A11,ListaIngredientes!$A$5:$F$155,6,FALSE),"") -> 0.00058823529 | H11: =IFERROR(E11*F11,"") -> 0.23529412
A12: 230 | B12: =IFERROR(VLOOKUP(A12,ListaIngredientes!$A$5:$F$155,2,FALSE),"") -> 0 | D12: kg | E12: 70 | F12: =IFERROR(VLOOKUP(A12,ListaIngredientes!$A$5:$F$155,6,FALSE),"") -> 0.149 | H12: =IFERROR(E12*F12,"") -> 10.43
A13: 174 | B13: =IFERROR(VLOOKUP(A13,ListaIngredientes!$A$5:$F$155,2,FALSE),"") -> Galvanatec 679 | D13: u | E13: 18 | F13: =IFERROR(VLOOKUP(A13,ListaIngredientes!$A$5:$F$155,6,FALSE),"") -> 0.8 | H13: =IFERROR(E13*F13,"") -> 14.4
A14: 176 | B14: =IFERROR(VLOOKUP(A14,ListaIngredientes!$A$5:$F$155,2,FALSE),"") -> forminha de brigadeiro | D14: U | E14: 18 | F14: =IFERROR(VLOOKUP(A14,ListaIngredientes!$A$5:$F$155,6,FALSE),"") -> 0.0215 | H14: =IFERROR(E14*F14,"") -> 0.387
B15: =IFERROR(VLOOKUP(A15,ListaIngredientes!$A$5:$F$155,2,FALSE),"") | F15: =IFERROR(VLOOKUP(A15,ListaIngredientes!$A$5:$F$155,6,FALSE),"") | H15: =IFERROR(E15*F15,"")
B16: =IFERROR(VLOOKUP(A16,ListaIngredientes!$A$5:$F$155,2,FALSE),"") | F16: =IFERROR(VLOOKUP(A16,ListaIngredientes!$A$5:$F$155,6,FALSE),"") | H16: =IFERROR(E16*F16,"")
B17: =IFERROR(VLOOKUP(A17,ListaIngredientes!$A$5:$F$155,2,FALSE),"") | D17: =IFERROR(VLOOKUP(A17,Tabela2[],3,FALSE),"") | F17: =IFERROR(VLOOKUP(A17,ListaIngredientes!$A$5:$F$155,6,FALSE),"") | H17: =IFERROR(E17*F17,"")
B18: =IFERROR(VLOOKUP(A18,ListaIngredientes!$A$5:$F$155,2,FALSE),"") | D18: =IFERROR(VLOOKUP(A18,Tabela2[],3,FALSE),"") | F18: =IFERROR(VLOOKUP(A18,ListaIngredientes!$A$5:$F$155,6,FALSE),"") | H18: =IFERROR(E18*F18,"")
B19: =IFERROR(VLOOKUP(A19,ListaIngredientes!$A$5:$F$155,2,FALSE),"") | D19: =IFERROR(VLOOKUP(A19,Tabela2[],3,FALSE),"") | F19: =IFERROR(VLOOKUP(A19,ListaIngredientes!$A$5:$F$155,6,FALSE),"") | H19: =IFERROR(E19*F19,"")
B20: =IFERROR(VLOOKUP(A20,ListaIngredientes!$A$5:$F$155,2,FALSE),"") | D20: =IFERROR(VLOOKUP(A20,Tabela2[],3,FALSE),"") | F20: =IFERROR(VLOOKUP(A20,ListaIngredientes!$A$5:$F$155,6,FALSE),"") | H20: =IFERROR(E20*F20,"")
B21: =IFERROR(VLOOKUP(A21,ListaIngredientes!$A$5:$F$155,2,FALSE),"") | D21: =IFERROR(VLOOKUP(A21,Tabela2[],3,FALSE),"") | F21: =IFERROR(VLOOKUP(A21,ListaIngredientes!$A$5:$F$155,6,FALSE),"") | H21: =IFERROR(E21*F21,"")
B22: =IFERROR(VLOOKUP(A22,ListaIngredientes!$A$5:$F$155,2,FALSE),"") | D22: =IFERROR(VLOOKUP(A22,Tabela2[],3,FALSE),"") | F22: =IFERROR(VLOOKUP(A22,ListaIngredientes!$A$5:$F$155,6,FALSE),"") | H22: =IFERROR(E22*F22,"")
B23: =IFERROR(VLOOKUP(A23,ListaIngredientes!$A$5:$F$155,2,FALSE),"") | D23: =IFERROR(VLOOKUP(A23,Tabela2[],3,FALSE),"") | F23: =IFERROR(VLOOKUP(A23,ListaIngredientes!$A$5:$F$155,6,FALSE),"") | H23: =IFERROR(E23*F23,"")
B24: =IFERROR(VLOOKUP(A24,ListaIngredientes!$A$5:$F$155,2,FALSE),"") | D24: =IFERROR(VLOOKUP(A24,Tabela2[],3,FALSE),"") | F24: =IFERROR(VLOOKUP(A24,ListaIngredientes!$A$5:$F$155,6,FALSE),"") | H24: =IFERROR(E24*F24,"")
B25: =IFERROR(VLOOKUP(A25,ListaIngredientes!$A$5:$F$155,2,FALSE),"") | D25: =IFERROR(VLOOKUP(A25,Tabela2[],3,FALSE),"") | F25: =IFERROR(VLOOKUP(A25,ListaIngredientes!$A$5:$F$155,6,FALSE),"") | H25: =IFERROR(E25*F25,"")
B26: =IFERROR(VLOOKUP(A26,ListaIngredientes!$A$5:$F$155,2,FALSE),"") | D26: =IFERROR(VLOOKUP(A26,Tabela2[],3,FALSE),"") | F26: =IFERROR(VLOOKUP(A26,ListaIngredientes!$A$5:$F$155,6,FALSE),"") | H26: =IFERROR(E26*F26,"")
B27: =IFERROR(VLOOKUP(A27,ListaIngredientes!$A$5:$F$155,2,FALSE),"") | D27: =IFERROR(VLOOKUP(A27,Tabela2[],3,FALSE),"") | F27: =IFERROR(VLOOKUP(A27,ListaIngredientes!$A$5:$F$155,6,FALSE),"") | H27: =IFERROR(E27*F27,"")
F28: soma | H28: =SUM(H8:H27) -> 45.452294

Sheet BRIGADEIRO DUO
A1: cod | B1: 503 | C1: =VLOOKUP(B1,PRODUTOS!$A$7:$E$204,2,FALSE) -> BRIGADEIRO DUO | E1: =C3 -> 4.4392552 | G1: SOBREMESA/DOCE
A2: Despesas Fixas | C2: 0.2 | E2: Preço Venda Unit | G2: =IFERROR(C3/(1-C2-C5),"") -> 14.797517
A3: Custo Unitário | C3: =IFERROR(C6/C4,"") -> 4.4392552 | E3: Luro s/Venda | G3: =G2*C5 -> 7.3987586
A4: Quantidade Produzida | C4: 9 | E4: Preço Praticado | G4: 15
A5: Lucro s/Venda | C5: 0.5 | E5: Lucro Praticado | G5: =1-C3/G4-C2 -> 0.50404965
A6: Gasto Total | C6: =H28 -> 39.953297 | E6: Lucro Praticado | G6: =G5*G4 -> 7.5607448
A7: cod Prod | B7: Descrição ingredientes | D7: unid | E7: quantiadade | F7: valor $ | H7: Subtotal
A8: 101 | B8: =IFERROR(VLOOKUP(A8,ListaIngredientes!$A$5:$F$155,2,FALSE),"") | D8: =IFERROR(VLOOKUP(A8,Tabela2[],3,FALSE),"") | E8: 9 | F8: =IFERROR(VLOOKUP(A8,ListaIngredientes!$A$5:$F$170,6,FALSE),"") | H8: =IFERROR(E8*F8,"")
A9: 105 | B9: =IFERROR(VLOOKUP(A9,ListaIngredientes!$A$5:$F$155,2,FALSE),"") -> Bananas | D9: =IFERROR(VLOOKUP(A9,Tabela2[],3,FALSE),"") -> duzias | E9: 20 | F9: =IFERROR(VLOOKUP(A9,ListaIngredientes!$A$5:$F$170,6,FALSE),"") -> 0.5 | H9: =IFERROR(E9*F9,"") -> 10
A10: 125 | B10: =IFERROR(VLOOKUP(A10,ListaIngredientes!$A$5:$F$155,2,FALSE),"") -> 0 | D10: =IFERROR(VLOOKUP(A10,Tabela2[],3,FALSE),"") -> 0 | E10: 70 | F10: =IFERROR(VLOOKUP(A10,ListaIngredientes!$A$5:$F$170,6,FALSE),"") -> 0 | H10: =IFERROR(E10*F10,"") -> 0
A11: 139 | B11: =IFERROR(VLOOKUP(A11,ListaIngredientes!$A$5:$F$155,2,FALSE),"") -> cravo da india | D11: =IFERROR(VLOOKUP(A11,Tabela2[],3,FALSE),"") -> g | E11: 1000 | F11: =IFERROR(VLOOKUP(A11,ListaIngredientes!$A$5:$F$170,6,FALSE),"") -> 0.00058823529 | H11: =IFERROR(E11*F11,"") -> 0.58823529
A12: 230 | B12: =IFERROR(VLOOKUP(A12,ListaIngredientes!$A$5:$F$155,2,FALSE),"") -> 0 | D12: kg | E12: 175 | F12: =IFERROR(VLOOKUP(A12,ListaIngredientes!$A$5:$F$170,6,FALSE),"") -> 0.149 | H12: =IFERROR(E12*F12,"") -> 26.075
A13: 135 | B13: =IFERROR(VLOOKUP(A13,ListaIngredientes!$A$5:$F$155,2,FALSE),"") -> ISOPOR DE PIZZA REDONDA | D13: u | E13: 9 | F13: =IFERROR(VLOOKUP(A13,ListaIngredientes!$A$5:$F$170,6,FALSE),"") -> 0.29 | H13: =IFERROR(E13*F13,"") -> 2.61
A14: 249 | B14: =IFERROR(VLOOKUP(A14,ListaIngredientes!$A$5:$F$155,2,FALSE),"") -> Whey Protein | D14: kg | E14: 40 | F14: =IFERROR(VLOOKUP(A14,ListaIngredientes!$A$5:$F$170,6,FALSE),"") -> 0.017001534 | H14: =IFERROR(E14*F14,"") -> 0.68006135
B15: =IFERROR(VLOOKUP(A15,ListaIngredientes!$A$5:$F$170,2,FALSE),"") | F15: =IFERROR(VLOOKUP(A15,ListaIngredientes!$A$5:$F$170,6,FALSE),"") | H15: =IFERROR(E15*F15,"")
B16: =IFERROR(VLOOKUP(A16,ListaIngredientes!$A$5:$F$170,2,FALSE),"") | F16: =IFERROR(VLOOKUP(A16,ListaIngredientes!$A$5:$F$170,6,FALSE),"") | H16: =IFERROR(E16*F16,"")
B17: =IFERROR(VLOOKUP(A17,ListaIngredientes!$A$5:$F$170,2,FALSE),"") | D17: =IFERROR(VLOOKUP(A17,Tabela2[],3,FALSE),"") | F17: =IFERROR(VLOOKUP(A17,ListaIngredientes!$A$5:$F$170,6,FALSE),"") | H17: =IFERROR(E17*F17,"")
B18: =IFERROR(VLOOKUP(A18,ListaIngredientes!$A$5:$F$170,2,FALSE),"") | D18: =IFERROR(VLOOKUP(A18,Tabela2[],3,FALSE),"") | F18: =IFERROR(VLOOKUP(A18,ListaIngredientes!$A$5:$F$170,6,FALSE),"") | H18: =IFERROR(E18*F18,"")
B19: =IFERROR(VLOOKUP(A19,ListaIngredientes!$A$5:$F$170,2,FALSE),"") | D19: =IFERROR(VLOOKUP(A19,Tabela2[],3,FALSE),"") | F19: =IFERROR(VLOOKUP(A19,ListaIngredientes!$A$5:$F$170,6,FALSE),"") | H19: =IFERROR(E19*F19,"")
B20: =IFERROR(VLOOKUP(A20,ListaIngredientes!$A$5:$F$170,2,FALSE),"") | D20: =IFERROR(VLOOKUP(A20,Tabela2[],3,FALSE),"") | F20: =IFERROR(VLOOKUP(A20,ListaIngredientes!$A$5:$F$170,6,FALSE),"") | H20: =IFERROR(E20*F20,"")
B21: =IFERROR(VLOOKUP(A21,ListaIngredientes!$A$5:$F$170,2,FALSE),"") | D21: =IFERROR(VLOOKUP(A21,Tabela2[],3,FALSE),"") | F21: =IFERROR(VLOOKUP(A21,ListaIngredientes!$A$5:$F$170,6,FALSE),"") | H21: =IFERROR(E21*F21,"")
B22: =IFERROR(VLOOKUP(A22,ListaIngredientes!$A$5:$F$170,2,FALSE),"") | D22: =IFERROR(VLOOKUP(A22,Tabela2[],3,FALSE),"") | F22: =IFERROR(VLOOKUP(A22,ListaIngredientes!$A$5:$F$170,6,FALSE),"") | H22: =IFERROR(E22*F22,"")
B23: =IFERROR(VLOOKUP(A23,ListaIngredientes!$A$5:$F$170,2,FALSE),"") | D23: =IFERROR(VLOOKUP(A23,Tabela2[],3,FALSE),"") | F23: =IFERROR(VLOOKUP(A23,ListaIngredientes!$A$5:$F$170,6,FALSE),"") | H23: =IFERROR(E23*F23,"")
B24: =IFERROR(VLOOKUP(A24,ListaIngredientes!$A$5:$F$170,2,FALSE),"") | D24: =IFERROR(VLOOKUP(A24,Tabela2[],3,FALSE),"") | F24: =IFERROR(VLOOKUP(A24,ListaIngredientes!$A$5:$F$170,6,FALSE),"") | H24: =IFERROR(E24*F24,"")
B25: =IFERROR(VLOOKUP(A25,ListaIngredientes!$A$5:$F$170,2,FALSE),"") | D25: =IFERROR(VLOOKUP(A25,Tabela2[],3,FALSE),"") | F25: =IFERROR(VLOOKUP(A25,ListaIngredientes!$A$5:$F$170,6,FALSE),"") | H25: =IFERROR(E25*F25,"")
B26: =IFERROR(VLOOKUP(A26,ListaIngredientes!$A$5:$F$170,2,FALSE),"") | D26: =IFERROR(VLOOKUP(A26,Tabela2[],3,FALSE),"") | F26: =IFERROR(VLOOKUP(A26,ListaIngredientes!$A$5:$F$170,6,FALSE),"") | H26: =IFERROR(E26*F26,"")
B27: =IFERROR(VLOOKUP(A27,ListaIngredientes!$A$5:$F$170,2,FALSE),"") | D27: =IFERROR(VLOOKUP(A27,Tabela2[],3,FALSE),"") | F27: =IFERROR(VLOOKUP(A27,ListaIngredientes!$A$5:$F$170,6,FALSE),"") | H27: =IFERROR(E27*F27,"")
F28: soma | H28: =SUM(H8:H27) -> 39.953297

Sheet BARRA DE CHOCOLATE
A1: cod | B1: 501 | C1: =VLOOKUP(B1,PRODUTOS!$A$7:$E$204,2,FALSE) -> P A S T E L | E1: =C3 -> 0.21538462 | G1: SOBREMESA/DOCE
A2: Despesas Fixas | C2: 0.2 | E2: Preço Venda Unit | G2: =IFERROR(C3/(1-C2-C5),"") -> 0.71794872
A3: Custo Unitário | C3: =IFERROR(C6/C4,"") -> 0.21538462 | E3: Luro s/Venda | G3: =G2*C5 -> 0.35897436
A4: Quantidade Produzida | C4: 13 | E4: Preço Praticado | G4: 15
A5: Lucro s/Venda | C5: 0.5 | E5: Lucro Praticado | G5: =1-C3/G4-C2 -> 0.78564103
A6: Gasto Total | C6: =H28 -> 2.8 | E6: Lucro Praticado | G6: =G5*G4 -> 11.784615
A7: cod Prod | B7: Descrição ingredientes | D7: unid | E7: quantiadade | F7: valor $ | H7: Subtotal
A8: 101 | B8: =IFERROR(VLOOKUP(A8,ListaIngredientes!$A$5:$F$155,2,FALSE),"") | D8: =IFERROR(VLOOKUP(A8,Tabela2[],3,FALSE),"") | E8: 7 | F8: =IFERROR(VLOOKUP(A8,ListaIngredientes!$A$5:$F$155,6,FALSE),"") | H8: =IFERROR(E8*F8,"")
A9: 223 | B9: =IFERROR(VLOOKUP(A9,ListaIngredientes!$A$5:$F$155,2,FALSE),"") -> SACO PASCOA 24X24 | D9: =IFERROR(VLOOKUP(A9,Tabela2[],3,FALSE),"") -> u | E9: 7 | F9: =IFERROR(VLOOKUP(A9,ListaIngredientes!$A$5:$F$155,6,FALSE),"") -> 0.4 | H9: =IFERROR(E9*F9,"") -> 2.8
A10: 125 | B10: =IFERROR(VLOOKUP(A10,ListaIngredientes!$A$5:$F$155,2,FALSE),"") -> 0 | D10: =IFERROR(VLOOKUP(A10,Tabela2[],3,FALSE),"") -> 0 | E10: 300 | F10: =IFERROR(VLOOKUP(A10,ListaIngredientes!$A$5:$F$155,6,FALSE),"") -> 0 | H10: =IFERROR(E10*F10,"") -> 0
B11: =IFERROR(VLOOKUP(A11,ListaIngredientes!$A$5:$F$155,2,FALSE),"") | D11: =IFERROR(VLOOKUP(A11,Tabela2[],3,FALSE),"") | F11: =IFERROR(VLOOKUP(A11,ListaIngredientes!$A$5:$F$155,6,FALSE),"") | H11: =IFERROR(E11*F11,"")
B12: =IFERROR(VLOOKUP(A12,ListaIngredientes!$A$5:$F$155,2,FALSE),"") | F12: =IFERROR(VLOOKUP(A12,ListaIngredientes!$A$5:$F$155,6,FALSE),"") | H12: =IFERROR(E12*F12,"")
B13: =IFERROR(VLOOKUP(A13,ListaIngredientes!$A$5:$F$155,2,FALSE),"") | F13: =IFERROR(VLOOKUP(A13,ListaIngredientes!$A$5:$F$155,6,FALSE),"") | H13: =IFERROR(E13*F13,"")
B14: =IFERROR(VLOOKUP(A14,ListaIngredientes!$A$5:$F$155,2,FALSE),"") | F14: =IFERROR(VLOOKUP(A14,ListaIngredientes!$A$5:$F$155,6,FALSE),"") | H14: =IFERROR(E14*F14,"")
B15: =IFERROR(VLOOKUP(A15,ListaIngredientes!$A$5:$F$155,2,FALSE),"") | F15: =IFERROR(VLOOKUP(A15,ListaIngredientes!$A$5:$F$155,6,FALSE),"") | H15: =IFERROR(E15*F15,"")
B16: =IFERROR(VLOOKUP(A16,ListaIngredientes!$A$5:$F$155,2,FALSE),"") | F16: =IFERROR(VLOOKUP(A16,ListaIngredientes!$A$5:$F$155,6,FALSE),"") | H16: =IFERROR(E16*F16,"")
B17: =IFERROR(VLOOKUP(A17,ListaIngredientes!$A$5:$F$155,2,FALSE),"") | D17: =IFERROR(VLOOKUP(A17,Tabela2[],3,FALSE),"") | F17: =IFERROR(VLOOKUP(A17,ListaIngredientes!$A$5:$F$155,6,FALSE),"") | H17: =IFERROR(E17*F17,"")
B18: =IFERROR(VLOOKUP(A18,ListaIngredientes!$A$5:$F$155,2,FALSE),"") | D18: =IFERROR(VLOOKUP(A18,Tabela2[],3,FALSE),"") | F18: =IFERROR(VLOOKUP(A18,ListaIngredientes!$A$5:$F$155,6,FALSE),"") | H18: =IFERROR(E18*F18,"")
B19: =IFERROR(VLOOKUP(A19,ListaIngredientes!$A$5:$F$155,2,FALSE),"") | D19: =IFERROR(VLOOKUP(A19,Tabela2[],3,FALSE),"") | F19: =IFERROR(VLOOKUP(A19,ListaIngredientes!$A$5:$F$155,6,FALSE),"") | H19: =IFERROR(E19*F19,"")
B20: =IFERROR(VLOOKUP(A20,ListaIngredientes!$A$5:$F$155,2,FALSE),"") | D20: =IFERROR(VLOOKUP(A20,Tabela2[],3,FALSE),"") | F20: =IFERROR(VLOOKUP(A20,ListaIngredientes!$A$5:$F$155,6,FALSE),"") | H20: =IFERROR(E20*F20,"")
B21: =IFERROR(VLOOKUP(A21,ListaIngredientes!$A$5:$F$155,2,FALSE),"") | D21: =IFERROR(VLOOKUP(A21,Tabela2[],3,FALSE),"") | F21: =IFERROR(VLOOKUP(A21,ListaIngredientes!$A$5:$F$155,6,FALSE),"") | H21: =IFERROR(E21*F21,"")
B22: =IFERROR(VLOOKUP(A22,ListaIngredientes!$A$5:$F$155,2,FALSE),"") | D22: =IFERROR(VLOOKUP(A22,Tabela2[],3,FALSE),"") | F22: =IFERROR(VLOOKUP(A22,ListaIngredientes!$A$5:$F$155,6,FALSE),"") | H22: =IFERROR(E22*F22,"")
B23: =IFERROR(VLOOKUP(A23,ListaIngredientes!$A$5:$F$155,2,FALSE),"") | D23: =IFERROR(VLOOKUP(A23,Tabela2[],3,FALSE),"") | F23: =IFERROR(VLOOKUP(A23,ListaIngredientes!$A$5:$F$155,6,FALSE),"") | H23: =IFERROR(E23*F23,"")
B24: =IFERROR(VLOOKUP(A24,ListaIngredientes!$A$5:$F$155,2,FALSE),"") | D24: =IFERROR(VLOOKUP(A24,Tabela2[],3,FALSE),"") | F24: =IFERROR(VLOOKUP(A24,ListaIngredientes!$A$5:$F$155,6,FALSE),"") | H24: =IFERROR(E24*F24,"")
B25: =IFERROR(VLOOKUP(A25,ListaIngredientes!$A$5:$F$155,2,FALSE),"") | D25: =IFERROR(VLOOKUP(A25,Tabela2[],3,FALSE),"") | F25: =IFERROR(VLOOKUP(A25,ListaIngredientes!$A$5:$F$155,6,FALSE),"") | H25: =IFERROR(E25*F25,"")
B26: =IFERROR(VLOOKUP(A26,ListaIngredientes!$A$5:$F$155,2,FALSE),"") | D26: =IFERROR(VLOOKUP(A26,Tabela2[],3,FALSE),"") | F26: =IFERROR(VLOOKUP(A26,ListaIngredientes!$A$5:$F$155,6,FALSE),"") | H26: =IFERROR(E26*F26,"")
B27: =IFERROR(VLOOKUP(A27,ListaIngredientes!$A$5:$F$155,2,FALSE),"") | D27: =IFERROR(VLOOKUP(A27,Tabela2[],3,FALSE),"") | F27: =IFERROR(VLOOKUP(A27,ListaIngredientes!$A$5:$F$155,6,FALSE),"") | H27: =IFERROR(E27*F27,"")
F28: soma | H28: =SUM(H8:H27) -> 2.8

Sheet CAJUZINHO
A1: cod | B1: 501 | C1: =VLOOKUP(B1,PRODUTOS!$A$7:$E$204,2,FALSE) -> P A S T E L | E1: =C3 -> 5.517537 | G1: SOBREMESA/DOCE
A2: Despesas Fixas | C2: 0.2 | E2: Preço Venda Unit | G2: =IFERROR(C3/(1-C2-C5),"") -> 18.39179
A3: Custo Unitário | C3: =IFERROR(C6/C4,"") -> 5.517537 | E3: Luro s/Venda | G3: =G2*C5 -> 9.1958949
A4: Quantidade Produzida | C4: 13 | E4: Preço Praticado | G4: 15
A5: Lucro s/Venda | C5: 0.5 | E5: Lucro Praticado | G5: =1-C3/G4-C2 -> 0.4321642
A6: Gasto Total | C6: =H28 -> 71.72798 | E6: Lucro Praticado | G6: =G5*G4 -> 6.482463
A7: cod Prod | B7: Descrição ingredientes | D7: unid | E7: quantiadade | F7: valor $ | H7: Subtotal
A8: 101 | B8: =IFERROR(VLOOKUP(A8,ListaIngredientes!$A$5:$F$155,2,FALSE),"") | D8: =IFERROR(VLOOKUP(A8,Tabela2[],3,FALSE),"") | E8: 8 | F8: =IFERROR(VLOOKUP(A8,ListaIngredientes!$A$5:$F$155,6,FALSE),"") | H8: =IFERROR(E8*F8,"")
A9: 102 | B9: =IFERROR(VLOOKUP(A9,ListaIngredientes!$A$5:$F$155,2,FALSE),"") -> Ovos Branco | D9: KG | E9: 35 | F9: =IFERROR(VLOOKUP(A9,ListaIngredientes!$A$5:$F$155,6,FALSE),"") -> 1.6666667 | H9: =IFERROR(E9*F9,"") -> 58.333333
A10: 230 | B10: =IFERROR(VLOOKUP(A10,ListaIngredientes!$A$5:$F$155,2,FALSE),"") -> 0 | D10: kg | E10: 45 | F10: =IFERROR(VLOOKUP(A10,ListaIngredientes!$A$5:$F$155,6,FALSE),"") -> 0.149 | H10: =IFERROR(E10*F10,"") -> 6.705
A11: 139 | B11: =IFERROR(VLOOKUP(A11,ListaIngredientes!$A$5:$F$155,2,FALSE),"") -> cravo da india | D11: =IFERROR(VLOOKUP(A11,Tabela2[],3,FALSE),"") -> g | E11: 200 | F11: =IFERROR(VLOOKUP(A11,ListaIngredientes!$A$5:$F$155,6,FALSE),"") -> 0.00058823529 | H11: =IFERROR(E11*F11,"") -> 0.11764706
A12: 143 | B12: =IFERROR(VLOOKUP(A12,ListaIngredientes!$A$5:$F$155,2,FALSE),"") -> 0 | D12: U | E12: 8 | F12: =IFERROR(VLOOKUP(A12,ListaIngredientes!$A$5:$F$155,6,FALSE),"") -> 0 | H12: =IFERROR(E12*F12,"") -> 0
A13: 176 | B13: =IFERROR(VLOOKUP(A13,ListaIngredientes!$A$5:$F$155,2,FALSE),"") -> forminha de brigadeiro | D13: U | E13: 8 | F13: =IFERROR(VLOOKUP(A13,ListaIngredientes!$A$5:$F$155,6,FALSE),"") -> 0.0215 | H13: =IFERROR(E13*F13,"") -> 0.172
A14: 174 | B14: =IFERROR(VLOOKUP(A14,ListaIngredientes!$A$5:$F$155,2,FALSE),"") -> Galvanatec 679 | D14: U | E14: 8 | F14: =IFERROR(VLOOKUP(A14,ListaIngredientes!$A$5:$F$155,6,FALSE),"") -> 0.8 | H14: =IFERROR(E14*F14,"") -> 6.4
B15: =IFERROR(VLOOKUP(A15,ListaIngredientes!$A$5:$F$155,2,FALSE),"") | F15: =IFERROR(VLOOKUP(A15,ListaIngredientes!$A$5:$F$155,6,FALSE),"") | H15: =IFERROR(E15*F15,"")
B16: =IFERROR(VLOOKUP(A16,ListaIngredientes!$A$5:$F$155,2,FALSE),"") | F16: =IFERROR(VLOOKUP(A16,ListaIngredientes!$A$5:$F$155,6,FALSE),"") | H16: =IFERROR(E16*F16,"")
B17: =IFERROR(VLOOKUP(A17,ListaIngredientes!$A$5:$F$155,2,FALSE),"") | D17: =IFERROR(VLOOKUP(A17,Tabela2[],3,FALSE),"") | F17: =IFERROR(VLOOKUP(A17,ListaIngredientes!$A$5:$F$155,6,FALSE),"") | H17: =IFERROR(E17*F17,"")
B18: =IFERROR(VLOOKUP(A18,ListaIngredientes!$A$5:$F$155,2,FALSE),"") | D18: =IFERROR(VLOOKUP(A18,Tabela2[],3,FALSE),"") | F18: =IFERROR(VLOOKUP(A18,ListaIngredientes!$A$5:$F$155,6,FALSE),"") | H18: =IFERROR(E18*F18,"")
B19: =IFERROR(VLOOKUP(A19,ListaIngredientes!$A$5:$F$155,2,FALSE),"") | D19: =IFERROR(VLOOKUP(A19,Tabela2[],3,FALSE),"") | F19: =IFERROR(VLOOKUP(A19,ListaIngredientes!$A$5:$F$155,6,FALSE),"") | H19: =IFERROR(E19*F19,"")
B20: =IFERROR(VLOOKUP(A20,ListaIngredientes!$A$5:$F$155,2,FALSE),"") | D20: =IFERROR(VLOOKUP(A20,Tabela2[],3,FALSE),"") | F20: =IFERROR(VLOOKUP(A20,ListaIngredientes!$A$5:$F$155,6,FALSE),"") | H20: =IFERROR(E20*F20,"")
B21: =IFERROR(VLOOKUP(A21,ListaIngredientes!$A$5:$F$155,2,FALSE),"") | D21: =IFERROR(VLOOKUP(A21,Tabela2[],3,FALSE),"") | F21: =IFERROR(VLOOKUP(A21,ListaIngredientes!$A$5:$F$155,6,FALSE),"") | H21: =IFERROR(E21*F21,"")
B22: =IFERROR(VLOOKUP(A22,ListaIngredientes!$A$5:$F$155,2,FALSE),"") | D22: =IFERROR(VLOOKUP(A22,Tabela2[],3,FALSE),"") | F22: =IFERROR(VLOOKUP(A22,ListaIngredientes!$A$5:$F$155,6,FALSE),"") | H22: =IFERROR(E22*F22,"")
B23: =IFERROR(VLOOKUP(A23,ListaIngredientes!$A$5:$F$155,2,FALSE),"") | D23: =IFERROR(VLOOKUP(A23,Tabela2[],3,FALSE),"") | F23: =IFERROR(VLOOKUP(A23,ListaIngredientes!$A$5:$F$155,6,FALSE),"") | H23: =IFERROR(E23*F23,"")
B24: =IFERROR(VLOOKUP(A24,ListaIngredientes!$A$5:$F$155,2,FALSE),"") | D24: =IFERROR(VLOOKUP(A24,Tabela2[],3,FALSE),"") | F24: =IFERROR(VLOOKUP(A24,ListaIngredientes!$A$5:$F$155,6,FALSE),"") | H24: =IFERROR(E24*F24,"")
B25: =IFERROR(VLOOKUP(A25,ListaIngredientes!$A$5:$F$155,2,FALSE),"") | D25: =IFERROR(VLOOKUP(A25,Tabela2[],3,FALSE),"") | F25: =IFERROR(VLOOKUP(A25,ListaIngredientes!$A$5:$F$155,6,FALSE),"") | H25: =IFERROR(E25*F25,"")
B26: =IFERROR(VLOOKUP(A26,ListaIngredientes!$A$5:$F$155,2,FALSE),"") | D26: =IFERROR(VLOOKUP(A26,Tabela2[],3,FALSE),"") | F26: =IFERROR(VLOOKUP(A26,ListaIngredientes!$A$5:$F$155,6,FALSE),"") | H26: =IFERROR(E26*F26,"")
B27: =IFERROR(VLOOKUP(A27,ListaIngredientes!$A$5:$F$155,2,FALSE),"") | D27: =IFERROR(VLOOKUP(A27,Tabela2[],3,FALSE),"") | F27: =IFERROR(VLOOKUP(A27,ListaIngredientes!$A$5:$F$155,6,FALSE),"") | H27: =IFERROR(E27*F27,"")
F28: soma | H28: =SUM(H8:H27) -> 71.72798

Sheet BEIJINHO
A1: cod | B1: 501 | C1: =VLOOKUP(B1,PRODUTOS!$A$7:$E$204,2,FALSE) -> P A S T E L | E1: =C3 -> 2.8140226 | G1: SOBREMESA/DOCE
A2: Despesas Fixas | C2: 0.2 | E2: Preço Venda Unit | G2: =IFERROR(C3/(1-C2-C5),"") -> 9.3800754
A3: Custo Unitário | C3: =IFERROR(C6/C4,"") -> 2.8140226 | E3: Luro s/Venda | G3: =G2*C5 -> 4.6900377
A4: Quantidade Produzida | C4: 13 | E4: Preço Praticado | G4: 15
A5: Lucro s/Venda | C5: 0.5 | E5: Lucro Praticado | G5: =1-C3/G4-C2 -> 0.61239849
A6: Gasto Total | C6: =H28 -> 36.582294 | E6: Lucro Praticado | G6: =G5*G4 -> 9.1859774
A7: cod Prod | B7: Descrição ingredientes | D7: unid | E7: quantiadade | F7: valor $ | H7: Subtotal
A8: 101 | B8: =IFERROR(VLOOKUP(A8,ListaIngredientes!$A$5:$F$155,2,FALSE),"") | D8: =IFERROR(VLOOKUP(A8,Tabela2[],3,FALSE),"") | E8: 18 | F8: =IFERROR(VLOOKUP(A8,ListaIngredientes!$A$5:$F$155,6,FALSE),"") | H8: =IFERROR(E8*F8,"")
A9: 126 | B9: =IFERROR(VLOOKUP(A9,ListaIngredientes!$A$5:$F$155,2,FALSE),"") -> CHOCOLTE BRANCO | D9: KG | E9: 70 | F9: =IFERROR(VLOOKUP(A9,ListaIngredientes!$A$5:$F$155,6,FALSE),"") -> 0.159 | H9: =IFERROR(E9*F9,"") -> 11.13
A10: 230 | B10: =IFERROR(VLOOKUP(A10,ListaIngredientes!$A$5:$F$155,2,FALSE),"") -> 0 | D10: kg | E10: 70 | F10: =IFERROR(VLOOKUP(A10,ListaIngredientes!$A$5:$F$155,6,FALSE),"") -> 0.149 | H10: =IFERROR(E10*F10,"") -> 10.43
A11: 139 | B11: =IFERROR(VLOOKUP(A11,ListaIngredientes!$A$5:$F$155,2,FALSE),"") -> cravo da india | D11: =IFERROR(VLOOKUP(A11,Tabela2[],3,FALSE),"") -> g | E11: 400 | F11: =IFERROR(VLOOKUP(A11,ListaIngredientes!$A$5:$F$155,6,FALSE),"") -> 0.00058823529 | H11: =IFERROR(E11*F11,"") -> 0.23529412
A12: 176 | B12: =IFERROR(VLOOKUP(A12,ListaIngredientes!$A$5:$F$155,2,FALSE),"") -> forminha de brigadeiro | D12: U | E12: 18 | F12: =IFERROR(VLOOKUP(A12,ListaIngredientes!$A$5:$F$155,6,FALSE),"") -> 0.0215 | H12: =IFERROR(E12*F12,"") -> 0.387
A13: 174 | B13: =IFERROR(VLOOKUP(A13,ListaIngredientes!$A$5:$F$155,2,FALSE),"") -> Galvanatec 679 | D13: U | E13: 18 | F13: =IFERROR(VLOOKUP(A13,ListaIngredientes!$A$5:$F$155,6,FALSE),"") -> 0.8 | H13: =IFERROR(E13*F13,"") -> 14.4
B14: =IFERROR(VLOOKUP(A14,ListaIngredientes!$A$5:$F$155,2,FALSE),"") | F14: =IFERROR(VLOOKUP(A14,ListaIngredientes!$A$5:$F$155,6,FALSE),"") | H14: =IFERROR(E14*F14,"")
B15: =IFERROR(VLOOKUP(A15,ListaIngredientes!$A$5:$F$155,2,FALSE),"") | F15: =IFERROR(VLOOKUP(A15,ListaIngredientes!$A$5:$F$155,6,FALSE),"") | H15: =IFERROR(E15*F15,"")
B16: =IFERROR(VLOOKUP(A16,ListaIngredientes!$A$5:$F$155,2,FALSE),"") | F16: =IFERROR(VLOOKUP(A16,ListaIngredientes!$A$5:$F$155,6,FALSE),"") | H16: =IFERROR(E16*F16,"")
B17: =IFERROR(VLOOKUP(A17,ListaIngredientes!$A$5:$F$155,2,FALSE),"") | D17: =IFERROR(VLOOKUP(A17,Tabela2[],3,FALSE),"") | F17: =IFERROR(VLOOKUP(A17,ListaIngredientes!$A$5:$F$155,6,FALSE),"") | H17: =IFERROR(E17*F17,"")
B18: =IFERROR(VLOOKUP(A18,ListaIngredientes!$A$5:$F$155,2,FALSE),"") | D18: =IFERROR(VLOOKUP(A18,Tabela2[],3,FALSE),"") | F18: =IFERROR(VLOOKUP(A18,ListaIngredientes!$A$5:$F$155,6,FALSE),"") | H18: =IFERROR(E18*F18,"")
